<?xml version='1.0' encoding='utf-8'?>
<robot name="g1_humanoid">
  <link name="pelvis">
    <inertial>
      <mass value="3.813" />
      <inertia ixx="0.010549" iyy="0.0093089" izz="0.0079184" ixy="0.0" ixz="0.0" iyz="0.0" />
    </inertial>
    <visual>
      <geometry>
        <box size="0.01 0.01 0.01" />
      </geometry>
    </visual>
    <collision>
      <geometry>
        <box size="0.01 0.01 0.01" />
      </geometry>
    </collision>
  </link>
  <link name="left_hip_pitch_link">
    <inertial>
      <mass value="1.35" />
      <inertia ixx="0.00181517" iyy="0.00153422" izz="0.00116212" ixy="0.0" ixz="0.0" iyz="0.0" />
    </inertial>
    <visual>
      <geometry>
        <box size="0.01 0.01 0.01" />
      </geometry>
    </visual>
    <collision>
      <geometry>
        <box size="0.01 0.01 0.01" />
      </geometry>
    </collision>
  </link>
  <link name="left_hip_roll_link">
    <inertial>
      <mass value="1.52" />
      <inertia ixx="0.00254986" iyy="0.00241169" izz="0.00148755" ixy="0.0" ixz="0.0" iyz="0.0" />
    </inertial>
    <visual>
      <geometry>
        <box size="0.01 0.01 0.01" />
      </geometry>
    </visual>
    <collision>
      <geometry>
        <box size="0.01 0.01 0.01" />
      </geometry>
    </collision>
  </link>
  <link name="left_hip_yaw_link">
    <inertial>
      <mass value="1.702" />
      <inertia ixx="0.00776166" iyy="0.00717575" izz="0.00160139" ixy="0.0" ixz="0.0" iyz="0.0" />
    </inertial>
    <visual>
      <geometry>
        <box size="0.01 0.01 0.01" />
      </geometry>
    </visual>
    <collision>
      <geometry>
        <box size="0.01 0.01 0.01" />
      </geometry>
    </collision>
  </link>
  <link name="left_knee_link">
    <inertial>
      <mass value="1.932" />
      <inertia ixx="0.0113804" iyy="0.0112778" izz="0.00146458" ixy="0.0" ixz="0.0" iyz="0.0" />
    </inertial>
    <visual>
      <geometry>
        <box size="0.01 0.01 0.01" />
      </geometry>
    </visual>
    <collision>
      <geometry>
        <box size="0.01 0.01 0.01" />
      </geometry>
    </collision>
  </link>
  <link name="left_ankle_pitch_link">
    <inertial>
      <mass value="0.074" />
      <inertia ixx="1.89e-05" iyy="1.40805e-05" izz="6.9195e-06" ixy="0.0" ixz="0.0" iyz="0.0" />
    </inertial>
    <visual>
      <geometry>
        <box size="0.01 0.01 0.01" />
      </geometry>
    </visual>
    <collision>
      <geometry>
        <box size="0.01 0.01 0.01" />
      </geometry>
    </collision>
  </link>
  <link name="left_ankle_roll_link">
    <inertial>
      <mass value="0.608" />
      <inertia ixx="0.00167218" iyy="0.0016161" izz="0.000217621" ixy="0.0" ixz="0.0" iyz="0.0" />
    </inertial>
    <visual>
      <geometry>
        <box size="0.01 0.01 0.01" />
      </geometry>
    </visual>
    <collision>
      <geometry>
        <box size="0.01 0.01 0.01" />
      </geometry>
    </collision>
  </link>
  <link name="right_hip_pitch_link">
    <inertial>
      <mass value="1.35" />
      <inertia ixx="0.00181517" iyy="0.00153422" izz="0.00116212" ixy="0.0" ixz="0.0" iyz="0.0" />
    </inertial>
    <visual>
      <geometry>
        <box size="0.01 0.01 0.01" />
      </geometry>
    </visual>
    <collision>
      <geometry>
        <box size="0.01 0.01 0.01" />
      </geometry>
    </collision>
  </link>
  <link name="right_hip_roll_link">
    <inertial>
      <mass value="1.52" />
      <inertia ixx="0.00254986" iyy="0.00241169" izz="0.00148755" ixy="0.0" ixz="0.0" iyz="0.0" />
    </inertial>
    <visual>
      <geometry>
        <box size="0.01 0.01 0.01" />
      </geometry>
    </visual>
    <collision>
      <geometry>
        <box size="0.01 0.01 0.01" />
      </geometry>
    </collision>
  </link>
  <link name="right_hip_yaw_link">
    <inertial>
      <mass value="1.702" />
      <inertia ixx="0.00776166" iyy="0.00717575" izz="0.00160139" ixy="0.0" ixz="0.0" iyz="0.0" />
    </inertial>
    <visual>
      <geometry>
        <box size="0.01 0.01 0.01" />
      </geometry>
    </visual>
    <collision>
      <geometry>
        <box size="0.01 0.01 0.01" />
      </geometry>
    </collision>
  </link>
  <link name="right_knee_link">
    <inertial>
      <mass value="1.932" />
      <inertia ixx="0.011374" iyy="0.0112843" izz="0.00146452" ixy="0.0" ixz="0.0" iyz="0.0" />
    </inertial>
    <visual>
      <geometry>
        <box size="0.01 0.01 0.01" />
      </geometry>
    </visual>
    <collision>
      <geometry>
        <box size="0.01 0.01 0.01" />
      </geometry>
    </collision>
  </link>
  <link name="right_ankle_pitch_link">
    <inertial>
      <mass value="0.074" />
      <inertia ixx="1.89e-05" iyy="1.40805e-05" izz="6.9195e-06" ixy="0.0" ixz="0.0" iyz="0.0" />
    </inertial>
    <visual>
      <geometry>
        <box size="0.01 0.01 0.01" />
      </geometry>
    </visual>
    <collision>
      <geometry>
        <box size="0.01 0.01 0.01" />
      </geometry>
    </collision>
  </link>
  <link name="right_ankle_roll_link">
    <inertial>
      <mass value="0.608" />
      <inertia ixx="0.00167218" iyy="0.0016161" izz="0.000217621" ixy="0.0" ixz="0.0" iyz="0.0" />
    </inertial>
    <visual>
      <geometry>
        <box size="0.01 0.01 0.01" />
      </geometry>
    </visual>
    <collision>
      <geometry>
        <box size="0.01 0.01 0.01" />
      </geometry>
    </collision>
  </link>
  <link name="torso_link">
    <inertial>
      <mass value="9.842" />
      <inertia ixx="0.135151" iyy="0.123088" izz="0.0327256" ixy="0.0" ixz="0.0" iyz="0.0" />
    </inertial>
    <visual>
      <geometry>
        <box size="0.01 0.01 0.01" />
      </geometry>
    </visual>
    <collision>
      <geometry>
        <box size="0.01 0.01 0.01" />
      </geometry>
    </collision>
  </link>
  <link name="left_shoulder_pitch_link">
    <inertial>
      <mass value="0.718" />
      <inertia ixx="0.000465864" iyy="0.000432842" izz="0.000406394" ixy="0.0" ixz="0.0" iyz="0.0" />
    </inertial>
    <visual>
      <geometry>
        <box size="0.01 0.01 0.01" />
      </geometry>
    </visual>
    <collision>
      <geometry>
        <box size="0.01 0.01 0.01" />
      </geometry>
    </collision>
  </link>
  <link name="left_shoulder_roll_link">
    <inertial>
      <mass value="0.643" />
      <inertia ixx="0.000691311" iyy="0.000618011" izz="0.000388977" ixy="0.0" ixz="0.0" iyz="0.0" />
    </inertial>
    <visual>
      <geometry>
        <box size="0.01 0.01 0.01" />
      </geometry>
    </visual>
    <collision>
      <geometry>
        <box size="0.01 0.01 0.01" />
      </geometry>
    </collision>
  </link>
  <link name="left_shoulder_yaw_link">
    <inertial>
      <mass value="0.734" />
      <inertia ixx="0.00106187" iyy="0.00103217" izz="0.000400661" ixy="0.0" ixz="0.0" iyz="0.0" />
    </inertial>
    <visual>
      <geometry>
        <box size="0.01 0.01 0.01" />
      </geometry>
    </visual>
    <collision>
      <geometry>
        <box size="0.01 0.01 0.01" />
      </geometry>
    </collision>
  </link>
  <link name="left_elbow_link">
    <inertial>
      <mass value="0.6" />
      <inertia ixx="0.000443035" iyy="0.000421612" izz="0.000259353" ixy="0.0" ixz="0.0" iyz="0.0" />
    </inertial>
    <visual>
      <geometry>
        <box size="0.01 0.01 0.01" />
      </geometry>
    </visual>
    <collision>
      <geometry>
        <box size="0.01 0.01 0.01" />
      </geometry>
    </collision>
  </link>
  <link name="left_wrist_roll_rubber_hand">
    <inertial>
      <mass value="0.356929" />
      <inertia ixx="0.00200292" iyy="0.0019426" izz="0.000195232" ixy="0.0" ixz="0.0" iyz="0.0" />
    </inertial>
    <visual>
      <geometry>
        <box size="0.01 0.01 0.01" />
      </geometry>
    </visual>
    <collision>
      <geometry>
        <box size="0.01 0.01 0.01" />
      </geometry>
    </collision>
  </link>
  <link name="right_shoulder_pitch_link">
    <inertial>
      <mass value="0.718" />
      <inertia ixx="0.000465864" iyy="0.000432842" izz="0.000406394" ixy="0.0" ixz="0.0" iyz="0.0" />
    </inertial>
    <visual>
      <geometry>
        <box size="0.01 0.01 0.01" />
      </geometry>
    </visual>
    <collision>
      <geometry>
        <box size="0.01 0.01 0.01" />
      </geometry>
    </collision>
  </link>
  <link name="right_shoulder_roll_link">
    <inertial>
      <mass value="0.643" />
      <inertia ixx="0.000691311" iyy="0.000618011" izz="0.000388977" ixy="0.0" ixz="0.0" iyz="0.0" />
    </inertial>
    <visual>
      <geometry>
        <box size="0.01 0.01 0.01" />
      </geometry>
    </visual>
    <collision>
      <geometry>
        <box size="0.01 0.01 0.01" />
      </geometry>
    </collision>
  </link>
  <link name="right_shoulder_yaw_link">
    <inertial>
      <mass value="0.734" />
      <inertia ixx="0.00106187" iyy="0.00103217" izz="0.000400661" ixy="0.0" ixz="0.0" iyz="0.0" />
    </inertial>
    <visual>
      <geometry>
        <box size="0.01 0.01 0.01" />
      </geometry>
    </visual>
    <collision>
      <geometry>
        <box size="0.01 0.01 0.01" />
      </geometry>
    </collision>
  </link>
  <link name="right_elbow_link">
    <inertial>
      <mass value="0.6" />
      <inertia ixx="0.000443035" iyy="0.000421612" izz="0.000259353" ixy="0.0" ixz="0.0" iyz="0.0" />
    </inertial>
    <visual>
      <geometry>
        <box size="0.01 0.01 0.01" />
      </geometry>
    </visual>
    <collision>
      <geometry>
        <box size="0.01 0.01 0.01" />
      </geometry>
    </collision>
  </link>
  <link name="right_wrist_roll_rubber_hand">
    <inertial>
      <mass value="0.356929" />
      <inertia ixx="0.00200292" iyy="0.0019426" izz="0.000195232" ixy="0.0" ixz="0.0" iyz="0.0" />
    </inertial>
    <visual>
      <geometry>
        <box size="0.01 0.01 0.01" />
      </geometry>
    </visual>
    <collision>
      <geometry>
        <box size="0.01 0.01 0.01" />
      </geometry>
    </collision>
  </link>
  <link name="waist_roll">
    <inertial>
      <mass value="0.001" />
      <inertia ixx="0.001" iyy="0.001" izz="0.001" ixy="0.0" ixz="0.0" iyz="0.0" />
    </inertial>
    <visual>
      <geometry>
        <box size="0.01 0.01 0.01" />
      </geometry>
    </visual>
    <collision>
      <geometry>
        <box size="0.01 0.01 0.01" />
      </geometry>
    </collision>
  </link>
  <link name="waist_pitch">
    <inertial>
      <mass value="0.001" />
      <inertia ixx="0.001" iyy="0.001" izz="0.001" ixy="0.0" ixz="0.0" iyz="0.0" />
    </inertial>
    <visual>
      <geometry>
        <box size="0.01 0.01 0.01" />
      </geometry>
    </visual>
    <collision>
      <geometry>
        <box size="0.01 0.01 0.01" />
      </geometry>
    </collision>
  </link>
  <link name="left_wrist_pitch">
    <inertial>
      <mass value="0.001" />
      <inertia ixx="0.001" iyy="0.001" izz="0.001" ixy="0.0" ixz="0.0" iyz="0.0" />
    </inertial>
    <visual>
      <geometry>
        <box size="0.01 0.01 0.01" />
      </geometry>
    </visual>
    <collision>
      <geometry>
        <box size="0.01 0.01 0.01" />
      </geometry>
    </collision>
  </link>
  <link name="left_wrist_yaw">
    <inertial>
      <mass value="0.001" />
      <inertia ixx="0.001" iyy="0.001" izz="0.001" ixy="0.0" ixz="0.0" iyz="0.0" />
    </inertial>
    <visual>
      <geometry>
        <box size="0.01 0.01 0.01" />
      </geometry>
    </visual>
    <collision>
      <geometry>
        <box size="0.01 0.01 0.01" />
      </geometry>
    </collision>
  </link>
  <link name="right_wrist_pitch">
    <inertial>
      <mass value="0.001" />
      <inertia ixx="0.001" iyy="0.001" izz="0.001" ixy="0.0" ixz="0.0" iyz="0.0" />
    </inertial>
    <visual>
      <geometry>
        <box size="0.01 0.01 0.01" />
      </geometry>
    </visual>
    <collision>
      <geometry>
        <box size="0.01 0.01 0.01" />
      </geometry>
    </collision>
  </link>
  <link name="right_wrist_yaw">
    <inertial>
      <mass value="0.001" />
      <inertia ixx="0.001" iyy="0.001" izz="0.001" ixy="0.0" ixz="0.0" iyz="0.0" />
    </inertial>
    <visual>
      <geometry>
        <box size="0.01 0.01 0.01" />
      </geometry>
    </visual>
    <collision>
      <geometry>
        <box size="0.01 0.01 0.01" />
      </geometry>
    </collision>
  </link>
  <joint name="left_hip_pitch_joint" type="revolute">
    <parent link="pelvis" />
    <child link="left_hip_pitch_link" />
    <origin xyz="0.0 0.0 0.0" rpy="0.0 0.0 0.0" />
    <axis xyz="0.0 1.0 0.0" />
    <limit lower="-2.5307" upper="2.8798" effort="100" velocity="10" />
  </joint>
  <joint name="left_hip_roll_joint" type="revolute">
    <parent link="left_hip_pitch_link" />
    <child link="left_hip_roll_link" />
    <origin xyz="0.0 0.0 0.0" rpy="0.0 0.0 0.0" />
    <axis xyz="1.0 0.0 0.0" />
    <limit lower="-0.5236" upper="2.9671" effort="100" velocity="10" />
  </joint>
  <joint name="left_hip_yaw_joint" type="revolute">
    <parent link="left_hip_roll_link" />
    <child link="left_hip_yaw_link" />
    <origin xyz="0.0 0.0 0.0" rpy="0.0 0.0 0.0" />
    <axis xyz="0.0 0.0 1.0" />
    <limit lower="-2.7576" upper="2.7576" effort="100" velocity="10" />
  </joint>
  <joint name="left_knee_joint" type="revolute">
    <parent link="left_hip_yaw_link" />
    <child link="left_knee_link" />
    <origin xyz="0.0 0.0 0.0" rpy="0.0 0.0 0.0" />
    <axis xyz="0.0 1.0 0.0" />
    <limit lower="-0.087267" upper="2.8798" effort="100" velocity="10" />
  </joint>
  <joint name="left_ankle_pitch_joint" type="revolute">
    <parent link="left_knee_link" />
    <child link="left_ankle_pitch_link" />
    <origin xyz="0.0 0.0 0.0" rpy="0.0 0.0 0.0" />
    <axis xyz="0.0 1.0 0.0" />
    <limit lower="-0.87267" upper="0.5236" effort="100" velocity="10" />
  </joint>
  <joint name="left_ankle_roll_joint" type="revolute">
    <parent link="left_ankle_pitch_link" />
    <child link="left_ankle_roll_link" />
    <origin xyz="0.0 0.0 0.0" rpy="0.0 0.0 0.0" />
    <axis xyz="1.0 0.0 0.0" />
    <limit lower="-0.2618" upper="0.2618" effort="100" velocity="10" />
  </joint>
  <joint name="right_hip_pitch_joint" type="revolute">
    <parent link="pelvis" />
    <child link="right_hip_pitch_link" />
    <origin xyz="0.0 0.0 0.0" rpy="0.0 0.0 0.0" />
    <axis xyz="0.0 1.0 0.0" />
    <limit lower="-2.5307" upper="2.8798" effort="100" velocity="10" />
  </joint>
  <joint name="right_hip_roll_joint" type="revolute">
    <parent link="right_hip_pitch_link" />
    <child link="right_hip_roll_link" />
    <origin xyz="0.0 0.0 0.0" rpy="0.0 0.0 0.0" />
    <axis xyz="1.0 0.0 0.0" />
    <limit lower="-2.9671" upper="0.5236" effort="100" velocity="10" />
  </joint>
  <joint name="right_hip_yaw_joint" type="revolute">
    <parent link="right_hip_roll_link" />
    <child link="right_hip_yaw_link" />
    <origin xyz="0.0 0.0 0.0" rpy="0.0 0.0 0.0" />
    <axis xyz="0.0 0.0 1.0" />
    <limit lower="-2.7576" upper="2.7576" effort="100" velocity="10" />
  </joint>
  <joint name="right_knee_joint" type="revolute">
    <parent link="right_hip_yaw_link" />
    <child link="right_knee_link" />
    <origin xyz="0.0 0.0 0.0" rpy="0.0 0.0 0.0" />
    <axis xyz="0.0 1.0 0.0" />
    <limit lower="-0.087267" upper="2.8798" effort="100" velocity="10" />
  </joint>
  <joint name="right_ankle_pitch_joint" type="revolute">
    <parent link="right_knee_link" />
    <child link="right_ankle_pitch_link" />
    <origin xyz="0.0 0.0 0.0" rpy="0.0 0.0 0.0" />
    <axis xyz="0.0 1.0 0.0" />
    <limit lower="-0.87267" upper="0.5236" effort="100" velocity="10" />
  </joint>
  <joint name="right_ankle_roll_joint" type="revolute">
    <parent link="right_ankle_pitch_link" />
    <child link="right_ankle_roll_link" />
    <origin xyz="0.0 0.0 0.0" rpy="0.0 0.0 0.0" />
    <axis xyz="1.0 0.0 0.0" />
    <limit lower="-0.2618" upper="0.2618" effort="100" velocity="10" />
  </joint>
  <joint name="waist_yaw_joint" type="revolute">
    <parent link="pelvis" />
    <child link="torso_link" />
    <origin xyz="0.0 0.0 0.0" rpy="0.0 0.0 0.0" />
    <axis xyz="0.0 0.0 1.0" />
    <limit lower="-2.618" upper="2.618" effort="100" velocity="10" />
  </joint>
  <joint name="left_shoulder_pitch_joint" type="revolute">
    <parent link="torso_link" />
    <child link="left_shoulder_pitch_link" />
    <origin xyz="0.0 0.0 0.0" rpy="0.0 0.0 0.0" />
    <axis xyz="0.0 1.0 0.0" />
    <limit lower="-3.0892" upper="2.6704" effort="100" velocity="10" />
  </joint>
  <joint name="left_shoulder_roll_joint" type="revolute">
    <parent link="left_shoulder_pitch_link" />
    <child link="left_shoulder_roll_link" />
    <origin xyz="0.0 0.0 0.0" rpy="0.0 0.0 0.0" />
    <axis xyz="1.0 0.0 0.0" />
    <limit lower="-1.5882" upper="2.2515" effort="100" velocity="10" />
  </joint>
  <joint name="left_shoulder_yaw_joint" type="revolute">
    <parent link="left_shoulder_roll_link" />
    <child link="left_shoulder_yaw_link" />
    <origin xyz="0.0 0.0 0.0" rpy="0.0 0.0 0.0" />
    <axis xyz="0.0 0.0 1.0" />
    <limit lower="-2.618" upper="2.618" effort="100" velocity="10" />
  </joint>
  <joint name="left_elbow_joint" type="revolute">
    <parent link="left_shoulder_yaw_link" />
    <child link="left_elbow_link" />
    <origin xyz="0.0 0.0 0.0" rpy="0.0 0.0 0.0" />
    <axis xyz="0.0 1.0 0.0" />
    <limit lower="-1.0472" upper="2.0944" effort="100" velocity="10" />
  </joint>
  <joint name="left_wrist_roll_joint" type="revolute">
    <parent link="left_elbow_link" />
    <child link="left_wrist_roll_rubber_hand" />
    <origin xyz="0.0 0.0 0.0" rpy="0.0 0.0 0.0" />
    <axis xyz="1.0 0.0 0.0" />
    <limit lower="-1.97222" upper="1.97222" effort="100" velocity="10" />
  </joint>
  <joint name="right_shoulder_pitch_joint" type="revolute">
    <parent link="torso_link" />
    <child link="right_shoulder_pitch_link" />
    <origin xyz="0.0 0.0 0.0" rpy="0.0 0.0 0.0" />
    <axis xyz="0.0 1.0 0.0" />
    <limit lower="-3.0892" upper="2.6704" effort="100" velocity="10" />
  </joint>
  <joint name="right_shoulder_roll_joint" type="revolute">
    <parent link="right_shoulder_pitch_link" />
    <child link="right_shoulder_roll_link" />
    <origin xyz="0.0 0.0 0.0" rpy="0.0 0.0 0.0" />
    <axis xyz="1.0 0.0 0.0" />
    <limit lower="-2.2515" upper="1.5882" effort="100" velocity="10" />
  </joint>
  <joint name="right_shoulder_yaw_joint" type="revolute">
    <parent link="right_shoulder_roll_link" />
    <child link="right_shoulder_yaw_link" />
    <origin xyz="0.0 0.0 0.0" rpy="0.0 0.0 0.0" />
    <axis xyz="0.0 0.0 1.0" />
    <limit lower="-2.618" upper="2.618" effort="100" velocity="10" />
  </joint>
  <joint name="right_elbow_joint" type="revolute">
    <parent link="right_shoulder_yaw_link" />
    <child link="right_elbow_link" />
    <origin xyz="0.0 0.0 0.0" rpy="0.0 0.0 0.0" />
    <axis xyz="0.0 1.0 0.0" />
    <limit lower="-1.0472" upper="2.0944" effort="100" velocity="10" />
  </joint>
  <joint name="right_wrist_roll_joint" type="revolute">
    <parent link="right_elbow_link" />
    <child link="right_wrist_roll_rubber_hand" />
    <origin xyz="0.0 0.0 0.0" rpy="0.0 0.0 0.0" />
    <axis xyz="1.0 0.0 0.0" />
    <limit lower="-1.97222" upper="1.97222" effort="100" velocity="10" />
  </joint>
</robot>